<?xml version="1.0" ?>
<robot name="colmena2" xmlns:xacro="http://www.ros.org/wiki/xacro">

  <xacro:include filename="$(find colmena2_description)/urdf/materials.xacro" />

  <link name="base_link"/>

  <link name="chassis">
    <inertial>
      <mass value="2.131"/>
      <origin xyz="0 0 0" rpy="0.0 0.0 0.0"/>
      <inertia 
        ixx="0.004055" 
        ixy="0.0" 
        ixz="0.0001573" 
        iyy="0.01032" 
        iyz="0.0" 
        izz="0.01298"
      />
    </inertial>
    <visual>
      <origin xyz="0 0 0" rpy="0 0 0"/>
      <geometry>
        <mesh filename="file://$(find colmena2_description)/meshes/chassis.stl" scale="0.001 0.001 0.001"/>
      </geometry>
      <material name="white"/>
    </visual>
    <collision>
      <origin xyz="0 0 0" rpy="0 0 0"/>
      <geometry>
        <mesh filename="file://$(find colmena2_description)/meshes/chassis.stl" scale="0.001 0.001 0.001"/>
      </geometry>
    </collision>
  </link>

  <link name="left_sprocket">
    <inertial>
      <mass value="0.239463"/>
      <origin xyz="0 0 0" rpy="0.0 0.0 0.0"/>
      <inertia 
        ixx="0.0000608" 
        ixy="0.0" 
        ixz="0.0" 
        iyy="0.0001084" 
        iyz="0.0" 
        izz="0.0000608"
      />
    </inertial>
    <visual>
      <origin xyz="0 0 0" rpy="0 0 0"/>
      <geometry>
        <mesh filename="file://$(find colmena2_description)/meshes/wheel.stl" scale="0.001 0.001 0.001"/>
      </geometry>
      <material name="silver"/>
    </visual>
    <collision>
      <origin xyz="0 0 0" rpy="0 0 0"/>
      <geometry>
        <mesh filename="file://$(find colmena2_description)/meshes/wheel.stl" scale="0.001 0.001 0.001"/>
      </geometry>
    </collision>
  </link>

  <link name="right_sprocket">
    <inertial>
      <mass value="0.239463"/>
      <origin xyz="0 0 0" rpy="0.0 0.0 0.0"/>
      <inertia 
        ixx="0.0000608" 
        ixy="0.0" 
        ixz="0.0" 
        iyy="0.0001084" 
        iyz="0.0" 
        izz="0.0000608"
      />
    </inertial>
    <visual>
      <origin xyz="0 0 0" rpy="0 0 0"/>
      <geometry>
        <mesh filename="file://$(find colmena2_description)/meshes/wheel.stl" scale="0.001 0.001 0.001"/>
      </geometry>
      <material name="silver"/>
    </visual>
    <collision>
      <origin xyz="0 0 0" rpy="0 0 0"/>
      <geometry>
        <mesh filename="file://$(find colmena2_description)/meshes/wheel.stl" scale="0.001 0.001 0.001"/>
      </geometry>
    </collision>
  </link>

  <link name="left_wheel">
    <inertial>
      <mass value="0.239463"/>
      <origin xyz="0 0 0" rpy="0.0 0.0 0.0"/>
      <inertia 
        ixx="0.0000608" 
        ixy="0.0" 
        ixz="0.0" 
        iyy="0.0001084" 
        iyz="0.0" 
        izz="0.0000608"
      />
    </inertial>
    <visual>
      <origin xyz="0 0 0" rpy="0 0 0"/>
      <geometry>
        <mesh filename="file://$(find colmena2_description)/meshes/wheel.stl" scale="0.001 0.001 0.001"/>
      </geometry>
      <material name="silver"/>
    </visual>
    <collision>
      <origin xyz="0 0 0" rpy="0 0 0"/>
      <geometry>
        <mesh filename="file://$(find colmena2_description)/meshes/wheel.stl" scale="0.001 0.001 0.001"/>
      </geometry>
    </collision>
  </link>

  <link name="right_wheel">
    <inertial>
      <mass value="0.239463"/>
      <origin xyz="0 0 0" rpy="0.0 0.0 0.0"/>
      <inertia 
        ixx="0.0000608" 
        ixy="0.0" 
        ixz="0.0" 
        iyy="0.0001084" 
        iyz="0.0" 
        izz="0.0000608"
      />
    </inertial>
    <visual>
      <origin xyz="0 0 0" rpy="0 0 0"/>
      <geometry>
        <mesh filename="file://$(find colmena2_description)/meshes/wheel.stl" scale="0.001 0.001 0.001"/>
      </geometry>
      <material name="silver"/>
    </visual>
    <collision>
      <origin xyz="0 0 0" rpy="0 0 0"/>
      <geometry>
        <mesh filename="file://$(find colmena2_description)/meshes/wheel.stl" scale="0.001 0.001 0.001"/>
      </geometry>
    </collision>
  </link>

  <link name="left_track">
    <inertial>
      <mass value="0.022541"/>
      <origin xyz="0 0 0" rpy="0.0 0.0 0.0"/>
      <inertia 
        ixx="0.0001033" 
        ixy="0.0" 
        ixz="0.0" 
        iyy="0.0009194" 
        iyz="0.0" 
        izz="0.0008376"
      />
    </inertial>
    <visual>
      <origin xyz="0 0 0" rpy="0 0 0"/>
      <geometry>
        <mesh filename="file://$(find colmena2_description)/meshes/track.stl" scale="0.001 0.001 0.001"/>
      </geometry>
      <material name="black"/>
    </visual>
  </link>
  
  <link name="right_track">
    <inertial>
      <mass value="0.022541"/>
      <origin xyz="0 0 0" rpy="0.0 0.0 0.0"/>
      <inertia 
        ixx="0.0001033" 
        ixy="0.0" 
        ixz="0.0" 
        iyy="0.0009194" 
        iyz="0.0" 
        izz="0.0008376"
      />
    </inertial>
    <visual>
      <origin xyz="0 0 0" rpy="0 0 0"/>
      <geometry>
        <mesh filename="file://$(find colmena2_description)/meshes/track.stl" scale="0.001 0.001 0.001"/>
      </geometry>
      <material name="black"/>
    </visual>
  </link>

  <link name="arm">
    <inertial>
      <mass value="0.369"/>
      <origin xyz="0 0 0" rpy="0.0 0.0 0.0"/>
      <inertia 
        ixx="0.0001981" 
        ixy="0.0" 
        ixz="-0.0000834" 
        iyy="0.002241" 
        iyz="0.0" 
        izz="0.002158"
      />
    </inertial>
    <visual>
      <origin xyz="0 0 0" rpy="0 0 0"/>
      <geometry>
        <mesh filename="file://$(find colmena2_description)/meshes/arm.stl" scale="0.001 0.001 0.001"/>
      </geometry>
      <material name="silver"/>
    </visual>
    <collision>
      <origin xyz="0 0 0" rpy="0 0 0"/>
      <geometry>
        <mesh filename="file://$(find colmena2_description)/meshes/arm.stl" scale="0.001 0.001 0.001"/>
      </geometry>
    </collision>
  </link>

  <link name="support">
    <inertial>
      <mass value="0.280"/>
      <origin xyz="0 0 0" rpy="0.0 0.0 0.0"/>
      <inertia 
        ixx="0.0005618" 
        ixy="0.0" 
        ixz="-0.0001057" 
        iyy="0.0006207" 
        iyz="0.0" 
        izz="0.0000886"
      />
    </inertial>
    <visual>
      <origin xyz="0 0 0" rpy="0 0 0"/>
      <geometry>
        <mesh filename="file://$(find colmena2_description)/meshes/support.stl" scale="0.001 0.001 0.001"/>
      </geometry>
      <material name="silver"/>
    </visual>
    <collision>
      <origin xyz="0 0 0" rpy="0 0 0"/>
      <geometry>
        <mesh filename="file://$(find colmena2_description)/meshes/support.stl" scale="0.001 0.001 0.001"/>
      </geometry>
    </collision>
  </link>

  <link name="panel">
    <inertial>
      <mass value="0.167"/>
      <origin xyz="0 0 0" rpy="0.0 0.0 0.0"/>
      <inertia 
        ixx="0.0002904" 
        ixy="0.0" 
        ixz="0.0001546" 
        iyy="0.0003574" 
        iyz="0.0" 
        izz="0.0004688"
      />
    </inertial>
    <visual>
      <origin xyz="0 0 0" rpy="0 0 0"/>
      <geometry>
        <mesh filename="file://$(find colmena2_description)/meshes/panel.stl" scale="0.001 0.001 0.001"/>
      </geometry>
      <material name="blue"/>
    </visual>
    <collision>
      <origin xyz="0 0 0" rpy="0 0 0"/>
      <geometry>
        <mesh filename="file://$(find colmena2_description)/meshes/panel.stl" scale="0.001 0.001 0.001"/>
      </geometry>
    </collision>
  </link>
  
  <joint name="ch_to_bl_joint" type="fixed">
    <parent link="base_link"/>
    <child link="chassis"/>
    <origin xyz="-0.002463 -0.000004 0.010086"/>
  </joint>

  <joint name="ls_to_ch_joint" type="continuous">
    <parent link="chassis"/>
    <child link="left_sprocket"/>
    <origin xyz="-0.097537 0.100004 -0.010086"/>
    <axis xyz="0 1 0"/>
  </joint>

  <joint name="rs_to_ch_joint" type="continuous">
    <parent link="chassis"/>
    <child link="right_sprocket"/>
    <origin xyz="-0.097537 -0.099996 -0.010086"/>
    <axis xyz="0 1 0"/>
  </joint>

  <joint name="lw_to_ch_joint" type="continuous">
    <parent link="chassis"/>
    <child link="left_wheel"/>
    <origin xyz="0.102463 0.100004 -0.010086"/>
    <axis xyz="0 1 0"/>
    <mimic joint="ls_to_ch_joint" multiplier="1" offset="0"/>
  </joint>

  <joint name="rw_to_ch_joint" type="continuous">
    <parent link="chassis"/>
    <child link="right_wheel"/>
    <origin xyz="0.102463 -0.099996 -0.010086"/>
    <axis xyz="0 1 0"/>
    <mimic joint="rs_to_ch_joint" multiplier="1" offset="0"/>
  </joint>
  
  <joint name="lt_to_ch_joint" type="fixed">
    <parent link="chassis"/>
    <child link="left_track"/>
    <origin xyz="0.002458 0.100004 -0.010086"/>
  </joint>

  <joint name="rt_to_ch_joint" type="fixed">
    <parent link="chassis"/>
    <child link="right_track"/>
    <origin xyz="0.002458 -0.099996 -0.010086"/>
  </joint>

  <joint name="arm_to_ch_joint" type="fixed">
    <parent link="chassis"/>
    <child link="arm"/>
    <origin xyz="0.243999 0.0 0.071118"/>
  </joint>

  <joint name="sp_to_ch_joint" type="fixed">
    <parent link="chassis"/>
    <child link="support"/>
    <origin xyz="-0.070318 0.0 0.112644"/>
  </joint>

  <joint name="pn_to_ch_joint" type="fixed">
    <parent link="chassis"/>
    <child link="panel"/>
    <origin xyz="-0.035091 0.000003 0.196115" rpy="0.0 ${pi/6} 0.0"/>
  </joint>
  
</robot>