<?xml version="1.0" ?>
<robot name="colmena2" xmlns:xacro="http://www.ros.org/wiki/xacro">

  <xacro:include filename="$(find colmena2_description)/urdf/materials.xacro" />

  <link name="base_link"/>

  <link name="chassis">
    <inertial>
      <mass value="2.088534"/>
      <origin xyz="0 0 0" rpy="0.0 0.0 0.0"/>
      <inertia 
        ixx="0.004459" 
        ixy="0.0" 
        ixz="0.00009" 
        iyy="0.009908" 
        iyz="0.0" 
        izz="0.01322"
      />
    </inertial>
    <visual>
      <origin xyz="0 0 0" rpy="0 0 0"/>
      <geometry>
        <mesh filename="file://$(find colmena2_description)/meshes/chasis.stl" scale="0.001 0.001 0.001"/>
      </geometry>
      <material name="white"/>
    </visual>
    <collision>
      <origin xyz="0 0 0" rpy="0 0 0"/>
      <geometry>
        <mesh filename="file://$(find colmena2_description)/meshes/chasis.stl" scale="0.001 0.001 0.001"/>
      </geometry>
    </collision>
  </link>

  <link name="right_sprocket">
    <inertial>
      <mass value="0.022541"/>
      <origin xyz="0 0 0" rpy="0.0 0.0 0.0"/>
      <inertia 
        ixx="0.000005" 
        ixy="0.0" 
        ixz="0.0" 
        iyy="0.000009" 
        iyz="0.0" 
        izz="0.000005"
      />
    </inertial>
    <visual>
      <origin xyz="0 0 0" rpy="0 0 0"/>
      <geometry>
        <mesh filename="file://$(find colmena2_description)/meshes/rueda.stl" scale="0.001 0.001 0.001"/>
      </geometry>
      <material name="silver"/>
    </visual>
    <collision>
      <origin xyz="0 0 0" rpy="0 0 0"/>
      <geometry>
        <mesh filename="file://$(find colmena2_description)/meshes/rueda.stl" scale="0.001 0.001 0.001"/>
      </geometry>
    </collision>
  </link>

  <link name="left_sprocket">
    <inertial>
      <mass value="0.022541"/>
      <origin xyz="0 0 0" rpy="0.0 0.0 0.0"/>
      <inertia 
        ixx="0.000005" 
        ixy="0.0" 
        ixz="0.0" 
        iyy="0.000009" 
        iyz="0.0" 
        izz="0.000005"
      />
    </inertial>
    <visual>
      <origin xyz="0 0 0" rpy="0 0 0"/>
      <geometry>
        <mesh filename="file://$(find colmena2_description)/meshes/rueda.stl" scale="0.001 0.001 0.001"/>
      </geometry>
      <material name="silver"/>
    </visual>
    <collision>
      <origin xyz="0 0 0" rpy="0 0 0"/>
      <geometry>
        <mesh filename="file://$(find colmena2_description)/meshes/rueda.stl" scale="0.001 0.001 0.001"/>
      </geometry>
    </collision>
  </link>

  <link name="right_wheel">
    <inertial>
      <mass value="0.022541"/>
      <origin xyz="0 0 0" rpy="0.0 0.0 0.0"/>
      <inertia 
        ixx="0.000005" 
        ixy="0.0" 
        ixz="0.0" 
        iyy="0.000009" 
        iyz="0.0" 
        izz="0.000005"
      />
    </inertial>
    <visual>
      <origin xyz="0 0 0" rpy="0 0 0"/>
      <geometry>
        <mesh filename="file://$(find colmena2_description)/meshes/rueda.stl" scale="0.001 0.001 0.001"/>
      </geometry>
      <material name="silver"/>
    </visual>
    <collision>
      <origin xyz="0 0 0" rpy="0 0 0"/>
      <geometry>
        <mesh filename="file://$(find colmena2_description)/meshes/rueda.stl" scale="0.001 0.001 0.001"/>
      </geometry>
    </collision>
  </link>

  <link name="left_wheel">
    <inertial>
      <mass value="0.022541"/>
      <origin xyz="0 0 0" rpy="0.0 0.0 0.0"/>
      <inertia 
        ixx="0.000005" 
        ixy="0.0" 
        ixz="0.0" 
        iyy="0.000009" 
        iyz="0.0" 
        izz="0.000005"
      />
    </inertial>
    <visual>
      <origin xyz="0 0 0" rpy="0 0 0"/>
      <geometry>
        <mesh filename="file://$(find colmena2_description)/meshes/rueda.stl" scale="0.001 0.001 0.001"/>
      </geometry>
      <material name="silver"/>
    </visual>
    <collision>
      <origin xyz="0 0 0" rpy="0 0 0"/>
      <geometry>
        <mesh filename="file://$(find colmena2_description)/meshes/rueda.stl" scale="0.001 0.001 0.001"/>
      </geometry>
    </collision>
  </link>
  
  <link name="right_track">
    <inertial>
      <mass value="0.022541"/>
      <origin xyz="0 0 0" rpy="0.0 0.0 0.0"/>
      <inertia 
        ixx="0.000064" 
        ixy="0.0" 
        ixz="0.0" 
        iyy="0.000599" 
        iyz="0.0" 
        izz="0.000541"
      />
    </inertial>
    <visual>
      <origin xyz="0 0 0" rpy="0 0 0"/>
      <geometry>
        <mesh filename="file://$(find colmena2_description)/meshes/oruga.stl" scale="0.001 0.001 0.001"/>
      </geometry>
      <material name="black"/>
    </visual>
  </link>

  <link name="left_track">
    <inertial>
      <mass value="0.022541"/>
      <origin xyz="0 0 0" rpy="0.0 0.0 0.0"/>
      <inertia 
        ixx="0.000064" 
        ixy="0.0" 
        ixz="0.0" 
        iyy="0.000599" 
        iyz="0.0" 
        izz="0.000541"
      />
    </inertial>
    <visual>
      <origin xyz="0 0 0" rpy="0 0 0"/>
      <geometry>
        <mesh filename="file://$(find colmena2_description)/meshes/oruga.stl" scale="0.001 0.001 0.001"/>
      </geometry>
      <material name="black"/>
    </visual>
  </link>
  
  <link name="arm">
    <inertial>
      <mass value="0.379695"/>
      <origin xyz="0 0 0" rpy="0.0 0.0 0.0"/>
      <inertia 
        ixx="0.000271" 
        ixy="0.0" 
        ixz="0.000359" 
        iyy="0.002343" 
        iyz="0.0" 
        izz="0.002193"
      />
    </inertial>
    <visual>
      <origin xyz="0 0 0" rpy="0 0 0"/>
      <geometry>
        <mesh filename="file://$(find colmena2_description)/meshes/brazo.stl" scale="0.001 0.001 0.001"/>
      </geometry>
      <material name="silver"/>
    </visual>
    <collision>
      <origin xyz="0 0 0" rpy="0 0 0"/>
      <geometry>
        <mesh filename="file://$(find colmena2_description)/meshes/brazo.stl" scale="0.001 0.001 0.001"/>
      </geometry>
    </collision>
  </link>

  <link name="support">
    <inertial>
      <mass value="0.279375"/>
      <origin xyz="0 0 0" rpy="0.0 0.0 0.0"/>
      <inertia 
        ixx="0.000571" 
        ixy="0.0" 
        ixz="-0.00063" 
        iyy="0.000615" 
        iyz="0.0" 
        izz="0.000074"
      />
    </inertial>
    <visual>
      <origin xyz="0 0 0" rpy="0 0 0"/>
      <geometry>
        <mesh filename="file://$(find colmena2_description)/meshes/soporte.stl" scale="0.001 0.001 0.001"/>
      </geometry>
      <material name="silver"/>
    </visual>
    <collision>
      <origin xyz="0 0 0" rpy="0 0 0"/>
      <geometry>
        <mesh filename="file://$(find colmena2_description)/meshes/soporte.stl" scale="0.001 0.001 0.001"/>
      </geometry>
    </collision>
  </link>

  <link name="panel">
    <inertial>
      <mass value="0.167424"/>
      <origin xyz="0 0 0" rpy="0.0 0.0 0.0"/>
      <inertia 
        ixx="0.000265" 
        ixy="0.0" 
        ixz="-0.000137" 
        iyy="0.000357" 
        iyz="0.0" 
        izz="0.000494"
      />
    </inertial>
    <visual>
      <origin xyz="0 0 0" rpy="0 0 0"/>
      <geometry>
        <mesh filename="file://$(find colmena2_description)/meshes/panel.stl" scale="0.001 0.001 0.001"/>
      </geometry>
      <material name="blue"/>
    </visual>
    <collision>
      <origin xyz="0 0 0" rpy="0 0 0"/>
      <geometry>
        <mesh filename="file://$(find colmena2_description)/meshes/soporte.stl" scale="0.001 0.001 0.001"/>
      </geometry>
    </collision>
  </link>
  
  <joint name="ch_to_bl_joint" type="fixed">
    <parent link="base_link"/>
    <child link="chassis"/>
    <origin xyz="0.0 0.0 0.044336"/>
  </joint>

  <joint name="rs_to_ch_joint" type="continuous">
    <parent link="chassis"/>
    <child link="right_sprocket"/>
    <origin xyz="-0.098356 -0.110004 -0.0075"/>
    <axis xyz="0 1 0"/>
  </joint>

  <joint name="ls_to_ch_joint" type="continuous">
    <parent link="chassis"/>
    <child link="left_sprocket"/>
    <origin xyz="-0.098356 0.109996 -0.0075"/>
    <axis xyz="0 1 0"/>
  </joint>

  <joint name="rw_to_ch_joint" type="continuous">
    <parent link="chassis"/>
    <child link="right_wheel"/>
    <origin xyz="0.101644 -0.110004 -0.0075"/>
    <axis xyz="0 1 0"/>
    <mimic joint="rs_to_ch_joint" multiplier="1" offset="0"/>
  </joint>

  <joint name="lw_to_ch_joint" type="continuous">
    <parent link="chassis"/>
    <child link="left_wheel"/>
    <origin xyz="0.101644 0.109996 -0.0075"/>
    <axis xyz="0 1 0"/>
    <mimic joint="ls_to_ch_joint" multiplier="1" offset="0"/>
  </joint>
  
  <joint name="rt_to_ch_joint" type="fixed">
    <parent link="chassis"/>
    <child link="right_track"/>
    <origin xyz="0.001644 -0.110004 -0.007731"/>
  </joint>

  <joint name="lt_to_ch_joint" type="fixed">
    <parent link="chassis"/>
    <child link="left_track"/>
    <origin xyz="0.001644 0.109996 -0.007731"/>
  </joint>
  
  <joint name="ar_to_ch_joint" type="fixed">
    <parent link="chassis"/>
    <child link="arm"/>
    <origin xyz="0.209638 -0.000084 0.045208" rpy="0 0.235619 0"/>
  </joint>

  <joint name="sp_to_ch_joint" type="fixed">
    <parent link="chassis"/>
    <child link="support"/>
    <origin xyz="-0.07745 -0.000005 0.104746" rpy="0 -0.087266 0"/>
  </joint>

  <joint name="pn_to_sp_joint" type="fixed">
    <parent link="support"/>
    <child link="panel"/>
    <origin xyz="0.035212 0.0 0.083208" rpy="0 0.523599 0"/>
  </joint>
  
</robot>