<?xml version="1.0" ?>
<robot name="colmena2" xmlns:xacro="http://www.ros.org/wiki/xacro">

  <xacro:include filename="$(find colmena2_description)/urdf/materials.xacro" />

  <link name="base_link"/>

  <link name="chassis">
    <inertial>
      <mass value="2.222"/>
      <origin xyz="0 0 0" rpy="0.0 0.0 0.0"/>
      <inertia 
        ixx="0.004757" 
        ixy="0.0" 
        ixz="0.0001595" 
        iyy="0.01069" 
        iyz="0.0" 
        izz="0.01402"
      />
    </inertial>
    <visual>
      <origin xyz="0 0 0" rpy="0 0 0"/>
      <geometry>
        <mesh filename="file://$(find colmena2_description)/meshes/chassis.stl" scale="0.001 0.001 0.001"/>
      </geometry>
      <material name="white"/>
    </visual>
    <collision>
      <origin xyz="0 0 0" rpy="0 0 0"/>
      <geometry>
        <mesh filename="file://$(find colmena2_description)/meshes/chassis.stl" scale="0.001 0.001 0.001"/>
      </geometry>
    </collision>
  </link>

  <link name="left_sprocket">
    <inertial>
      <mass value="0.239463"/>
      <origin xyz="0 0 0" rpy="0.0 0.0 0.0"/>
      <inertia 
        ixx="0.0000608" 
        ixy="0.0" 
        ixz="0.0" 
        iyy="0.0001084" 
        iyz="0.0" 
        izz="0.0000608"
      />
    </inertial>
    <visual>
      <origin xyz="0 0 0" rpy="0 0 0"/>
      <geometry>
        <mesh filename="file://$(find colmena2_description)/meshes/wheel.stl" scale="0.001 0.001 0.001"/>
      </geometry>
      <material name="silver"/>
    </visual>
    <collision>
      <origin xyz="0 0 0" rpy="0 0 0"/>
      <geometry>
        <mesh filename="file://$(find colmena2_description)/meshes/wheel.stl" scale="0.001 0.001 0.001"/>
      </geometry>
    </collision>
  </link>

  <link name="right_sprocket">
    <inertial>
      <mass value="0.239463"/>
      <origin xyz="0 0 0" rpy="0.0 0.0 0.0"/>
      <inertia 
        ixx="0.0000608" 
        ixy="0.0" 
        ixz="0.0" 
        iyy="0.0001084" 
        iyz="0.0" 
        izz="0.0000608"
      />
    </inertial>
    <visual>
      <origin xyz="0 0 0" rpy="0 0 0"/>
      <geometry>
        <mesh filename="file://$(find colmena2_description)/meshes/wheel.stl" scale="0.001 0.001 0.001"/>
      </geometry>
      <material name="silver"/>
    </visual>
    <collision>
      <origin xyz="0 0 0" rpy="0 0 0"/>
      <geometry>
        <mesh filename="file://$(find colmena2_description)/meshes/wheel.stl" scale="0.001 0.001 0.001"/>
      </geometry>
    </collision>
  </link>

  <link name="left_wheel">
    <inertial>
      <mass value="0.239463"/>
      <origin xyz="0 0 0" rpy="0.0 0.0 0.0"/>
      <inertia 
        ixx="0.0000608" 
        ixy="0.0" 
        ixz="0.0" 
        iyy="0.0001084" 
        iyz="0.0" 
        izz="0.0000608"
      />
    </inertial>
    <visual>
      <origin xyz="0 0 0" rpy="0 0 0"/>
      <geometry>
        <mesh filename="file://$(find colmena2_description)/meshes/wheel.stl" scale="0.001 0.001 0.001"/>
      </geometry>
      <material name="silver"/>
    </visual>
    <collision>
      <origin xyz="0 0 0" rpy="0 0 0"/>
      <geometry>
        <mesh filename="file://$(find colmena2_description)/meshes/wheel.stl" scale="0.001 0.001 0.001"/>
      </geometry>
    </collision>
  </link>

  <link name="right_wheel">
    <inertial>
      <mass value="0.239463"/>
      <origin xyz="0 0 0" rpy="0.0 0.0 0.0"/>
      <inertia 
        ixx="0.0000608" 
        ixy="0.0" 
        ixz="0.0" 
        iyy="0.0001084" 
        iyz="0.0" 
        izz="0.0000608"
      />
    </inertial>
    <visual>
      <origin xyz="0 0 0" rpy="0 0 0"/>
      <geometry>
        <mesh filename="file://$(find colmena2_description)/meshes/wheel.stl" scale="0.001 0.001 0.001"/>
      </geometry>
      <material name="silver"/>
    </visual>
    <collision>
      <origin xyz="0 0 0" rpy="0 0 0"/>
      <geometry>
        <mesh filename="file://$(find colmena2_description)/meshes/wheel.stl" scale="0.001 0.001 0.001"/>
      </geometry>
    </collision>
  </link>

  <link name="left_track">
    <inertial>
      <mass value="0.022541"/>
      <origin xyz="0 0 0" rpy="0.0 0.0 0.0"/>
      <inertia 
        ixx="0.0001033" 
        ixy="0.0" 
        ixz="0.0" 
        iyy="0.0009194" 
        iyz="0.0" 
        izz="0.0008376"
      />
    </inertial>
    <visual>
      <origin xyz="0 0 0" rpy="0 0 0"/>
      <geometry>
        <mesh filename="file://$(find colmena2_description)/meshes/track.stl" scale="0.001 0.001 0.001"/>
      </geometry>
      <material name="black"/>
    </visual>
  </link>
  
  <link name="right_track">
    <inertial>
      <mass value="0.022541"/>
      <origin xyz="0 0 0" rpy="0.0 0.0 0.0"/>
      <inertia 
        ixx="0.0001033" 
        ixy="0.0" 
        ixz="0.0" 
        iyy="0.0009194" 
        iyz="0.0" 
        izz="0.0008376"
      />
    </inertial>
    <visual>
      <origin xyz="0 0 0" rpy="0 0 0"/>
      <geometry>
        <mesh filename="file://$(find colmena2_description)/meshes/track.stl" scale="0.001 0.001 0.001"/>
      </geometry>
      <material name="black"/>
    </visual>
  </link>
  
  <joint name="ch_to_bl_joint" type="fixed">
    <parent link="base_link"/>
    <child link="chassis"/>
    <origin xyz="-0.002361 -0.000004 0.009671"/>
  </joint>

  <joint name="ls_to_ch_joint" type="continuous">
    <parent link="chassis"/>
    <child link="left_sprocket"/>
    <origin xyz="-0.097639 0.110004 -0.009671"/>
    <axis xyz="0 1 0"/>
  </joint>

  <joint name="rs_to_ch_joint" type="continuous">
    <parent link="chassis"/>
    <child link="right_sprocket"/>
    <origin xyz="-0.097639 -0.109996 -0.009671"/>
    <axis xyz="0 1 0"/>
  </joint>

  <joint name="lw_to_ch_joint" type="continuous">
    <parent link="chassis"/>
    <child link="left_wheel"/>
    <origin xyz="0.102361 0.110004 -0.009671"/>
    <axis xyz="0 1 0"/>
    <mimic joint="ls_to_ch_joint" multiplier="1" offset="0"/>
  </joint>

  <joint name="rw_to_ch_joint" type="continuous">
    <parent link="chassis"/>
    <child link="right_wheel"/>
    <origin xyz="0.102361 -0.109996 -0.009671"/>
    <axis xyz="0 1 0"/>
    <mimic joint="rs_to_ch_joint" multiplier="1" offset="0"/>
  </joint>
  
  <joint name="lt_to_ch_joint" type="fixed">
    <parent link="chassis"/>
    <child link="left_track"/>
    <origin xyz="0.002356 0.110004 -0.009671"/>
  </joint>

  <joint name="rt_to_ch_joint" type="fixed">
    <parent link="chassis"/>
    <child link="right_track"/>
    <origin xyz="0.002356 -0.109996 -0.009671"/>
  </joint>
  
</robot>